Thu Dec 29 22:12:32 2022 - INFO  - Start environmental preparation.
Thu Dec 29 22:16:30 2022 - INFO  - End of environmental preparation!
Thu Dec 29 22:16:32 2022 - INFO  - Start to run testcase.
cobblerd does not appear to be running/accessible: ConnectionRefusedError(111, 'Connection refused')
Traceback (most recent call last):
  File "/usr/bin/cobbler", line 35, in <module>
    sys.exit(app.main())
  File "/usr/lib/python3.9/site-packages/cobbler/cli.py", line 852, in main
    rc = cli.run(sys.argv)
  File "/usr/lib/python3.9/site-packages/cobbler/cli.py", line 418, in run
    self.token = self.remote.login("", self.shared_secret)
  File "/usr/lib64/python3.9/xmlrpc/client.py", line 1122, in __call__
    return self.__send(self.__name, args)
  File "/usr/lib64/python3.9/xmlrpc/client.py", line 1464, in __request
    response = self.__transport.request(
  File "/usr/lib64/python3.9/xmlrpc/client.py", line 1166, in request
    return self.single_request(host, handler, request_body, verbose)
  File "/usr/lib64/python3.9/xmlrpc/client.py", line 1196, in single_request
    raise ProtocolError(
xmlrpc.client.ProtocolError: <ProtocolError for 127.0.0.1:80/cobbler_api: 503 Service Unavailable>
Thu Dec 29 22:16:48 2022 - ERROR - Failed option: package add
Thu Dec 29 22:16:50 2022 - ERROR - oe_test_cobbler_package.sh line 33
exception on server: 'internal error, unknown package name OpenEuler1'
Thu Dec 29 22:17:16 2022 - ERROR - Failed option: package copy
Thu Dec 29 22:17:19 2022 - ERROR - oe_test_cobbler_package.sh line 37
exception on server: 'internal error, unknown package name openEuler1'
Thu Dec 29 22:17:46 2022 - ERROR - Failed option: package edit
Thu Dec 29 22:17:48 2022 - ERROR - oe_test_cobbler_package.sh line 41
Thu Dec 29 22:18:03 2022 - ERROR - Failed option: package list
Thu Dec 29 22:18:05 2022 - ERROR - oe_test_cobbler_package.sh line 43
Thu Dec 29 22:18:20 2022 - ERROR - Failed option: package find
Thu Dec 29 22:18:21 2022 - ERROR - oe_test_cobbler_package.sh line 45
exception on server: 'internal error, unknown package name OpenEuler1'
exception on server: 'internal error, unknown package name OpenEuler2'
Thu Dec 29 22:19:10 2022 - ERROR - Failed option: package rename
Thu Dec 29 22:19:12 2022 - ERROR - oe_test_cobbler_package.sh line 53
Thu Dec 29 22:19:25 2022 - ERROR - Failed option: package report
Thu Dec 29 22:19:27 2022 - ERROR - oe_test_cobbler_package.sh line 55
Thu Dec 29 22:19:28 2022 - INFO  - End to run testcase.
Thu Dec 29 22:19:30 2022 - ERROR - failed to execute the case.
Thu Dec 29 22:19:31 2022 - INFO  - Start to restore the test environment.
Thu Dec 29 22:21:03 2022 - INFO  - End to restore the test environment.
